Workbook

Sheet All stores
A1: Store | B1: Takings
A2: Store 01 | B2: ='Store 01'!B42 -> 112056.49
A3: Store 02 | B3: ='Store 02'!B42 -> 91645.71
A4: Store 03 | B4: ='Store 03'!B42 -> 98439.56
A5: Store 04 | B5: ='Store 04'!B42 -> 101509.71
A6: Store 05 | B6: ='Store 05'!B42 -> 110762.87
A7: Store 06 | B7: ='Store 06'!B42 -> 88041.94
A8: Store 07 | B8: ='Store 07'!B42 -> 94562.91
A9: Store 08 | B9: ='Store 08'!B42 -> 111700.84
A10: Store 09 | B10: ='Store 09'!B42 -> 101365.81
A11: Store 10 | B11: ='Store 10'!B42 -> 107557.54
A12: Store 11 | B12: ='Store 11'!B42 -> 97461.37
A13: Store 12 | B13: ='Store 12'!B42 -> 92811.99
A14: Store 13 | B14: ='Store 13'!B42 -> 96876.49
A15: Store 14 | B15: ='Store 14'!B42 -> 93769.79
A16: Store 15 | B16: ='Store 15'!B42 -> 94101.87
A17: Store 16 | B17: ='Store 16'!B42 -> 109958.62
A18: Store 17 | B18: ='Store 17'!B42 -> 92048.42
A19: Store 18 | B19: ='Store 18'!B42 -> 87299.13
A20: Store 19 | B20: ='Store 19'!B42 -> 99552.29
A21: Store 20 | B21: ='Store 20'!B42 -> 117422.84
A22: Store 21 | B22: ='Store 21'!B42 -> 97967.14
A23: Store 22 | B23: ='Store 22'!B42 -> 113924.21
A24: Store 23 | B24: ='Store 23'!B42 -> 100241.19
A25: Store 24 | B25: ='Store 24'!B42 -> 111991.86
A26: Store 25 | B26: ='Store 25'!B42 -> 103391.83
A27: Store 26 | B27: ='Store 26'!B42 -> 109100
A28: Store 27 | B28: ='Store 27'!B42 -> 98951.62
A29: Store 28 | B29: ='Store 28'!B42 -> 110283.72
A30: Store 29 | B30: ='Store 29'!B42 -> 108556.11
A31: Store 30 | B31: ='Store 30'!B42 -> 111730.38
A32: Store 31 | B32: ='Store 31'!B42 -> 100643.89
A33: Store 32 | B33: ='Store 32'!B42 -> 84773.19
A34: Store 33 | B34: ='Store 33'!B42 -> 87208.95
A35: Store 34 | B35: ='Store 34'!B42 -> 91823.03
A36: Store 35 | B36: ='Store 35'!B42 -> 100079.79
A37: Store 36 | B37: ='Store 36'!B42 -> 88856.31
A38: Store 37 | B38: ='Store 37'!B42 -> 99031.09
A39: Store 38 | B39: ='Store 38'!B42 -> 94996.32
A40: Store 39 | B40: ='Store 39'!B42 -> 92050.63
...

Sheet Store 01
A1: Day | B1: Takings
A2: 1 | B2: 2869.51
A3: 2 | B3: 2774.08
A4: 3 | B4: 3501.35
A5: 4 | B5: 4675.74
A6: 5 | B6: 2577.1
A7: 6 | B7: 4498.57
A8: 7 | B8: 3105.76
A9: 8 | B9: 2120.77
A10: 9 | B10: 1.75
A11: 10 | B11: 3747.77
A12: 11 | B12: 4109.32
A13: 12 | B13: 2440.57
... A41: 40 | B41: 1547.73
A42: Total | B42: =SUM(B2:B41) -> 112056.49

Sheet Store 02
A1: Day | B1: Takings
A2: 1 | B2: 582.39
A3: 2 | B3: 14.96
A4: 3 | B4: 1511.95
A5: 4 | B5: 469.83
A6: 5 | B6: 159.25
A7: 6 | B7: 958.35
A8: 7 | B8: 2952.9
A9: 8 | B9: 757.75
A10: 9 | B10: 1826.94
A11: 10 | B11: 2956.36
A12: 11 | B12: 2981.89
A13: 12 | B13: 4263.95
... A41: 40 | B41: 4556.05
A42: Total | B42: =SUM(B2:B41) -> 91645.71

Sheet Store 03
A1: Day | B1: Takings
A2: 1 | B2: 3440.33
A3: 2 | B3: 1037.6
A4: 3 | B4: 179.97
A5: 4 | B5: 1260.5
A6: 5 | B6: 3300.1
A7: 6 | B7: 2567.82
A8: 7 | B8: 4244.08
A9: 8 | B9: 3632.04
A10: 9 | B10: 4695.35
A11: 10 | B11: 3918.16
A12: 11 | B12: 650.99
A13: 12 | B13: 4628.28
... A41: 40 | B41: 4894.6
A42: Total | B42: =SUM(B2:B41) -> 98439.56

Sheet Store 04
A1: Day | B1: Takings
A2: 1 | B2: 2450.68
A3: 2 | B3: 632.29
A4: 3 | B4: 1458.84
A5: 4 | B5: 4318.23
A6: 5 | B6: 841.61
A7: 6 | B7: 1044.08
A8: 7 | B8: 2299.78
A9: 8 | B9: 1449.5
A10: 9 | B10: 3452.09
A11: 10 | B11: 2437.43
A12: 11 | B12: 1622.63
A13: 12 | B13: 1263.85
... A41: 40 | B41: 3377.79
A42: Total | B42: =SUM(B2:B41) -> 101509.71

Sheet Store 05
A1: Day | B1: Takings
A2: 1 | B2: 979.75
A3: 2 | B3: 2037.43
A4: 3 | B4: 378.88
A5: 4 | B5: 2150.13
A6: 5 | B6: 3250.62
A7: 6 | B7: 2585.86
A8: 7 | B8: 4439.88
A9: 8 | B9: 4035.28
A10: 9 | B10: 4898.35
A11: 10 | B11: 3152.86
A12: 11 | B12: 2648.17
A13: 12 | B13: 769.88
... A41: 40 | B41: 3696.1
A42: Total | B42: =SUM(B2:B41) -> 110762.87

Sheet Store 06
A1: Day | B1: Takings
A2: 1 | B2: 2033.24
A3: 2 | B3: 4585.98
A4: 3 | B4: 1984.18
A5: 4 | B5: 459.05
A6: 5 | B6: 3553.02
A7: 6 | B7: 3503.75
A8: 7 | B8: 4040.44
A9: 8 | B9: 4678.93
A10: 9 | B10: 1368.96
A11: 10 | B11: 3346.57
A12: 11 | B12: 1899.22
A13: 12 | B13: 748.17
... A41: 40 | B41: 1287.42
A42: Total | B42: =SUM(B2:B41) -> 88041.94

Sheet Store 07
A1: Day | B1: Takings
A2: 1 | B2: 1207.43
A3: 2 | B3: 3419.61
A4: 3 | B4: 3477.24
A5: 4 | B5: 129
A6: 5 | B6: 4872.1
A7: 6 | B7: 2215.82
A8: 7 | B8: 2268.93
A9: 8 | B9: 2051.57
A10: 9 | B10: 1358.1
A11: 10 | B11: 3743.68
A12: 11 | B12: 3703.02
A13: 12 | B13: 210.41
... A41: 40 | B41: 971.77
A42: Total | B42: =SUM(B2:B41) -> 94562.91

Sheet Store 08
A1: Day | B1: Takings
A2: 1 | B2: 1561.34
A3: 2 | B3: 639.32
A4: 3 | B4: 2319.52
A5: 4 | B5: 4374.73
A6: 5 | B6: 2122.34
A7: 6 | B7: 3942.79
A8: 7 | B8: 23.77
A9: 8 | B9: 4758.87
A10: 9 | B10: 2563.88
A11: 10 | B11: 1998.48
A12: 11 | B12: 4889.18
A13: 12 | B13: 1435.5
... A41: 40 | B41: 4008.23
A42: Total | B42: =SUM(B2:B41) -> 111700.84

Sheet Store 09
A1: Day | B1: Takings
A2: 1 | B2: 1552.49
A3: 2 | B3: 3066.95
A4: 3 | B4: 2073.76
A5: 4 | B5: 4836.7
A6: 5 | B6: 1031.71
A7: 6 | B7: 440.7
A8: 7 | B8: 3053.27
A9: 8 | B9: 2333.36
A10: 9 | B10: 2463.63
A11: 10 | B11: 832
A12: 11 | B12: 4314.52
A13: 12 | B13: 1494.77
... A41: 40 | B41: 4589.87
A42: Total | B42: =SUM(B2:B41) -> 101365.81

Sheet Store 10
A1: Day | B1: Takings
A2: 1 | B2: 384.71
A3: 2 | B3: 3762.93
A4: 3 | B4: 1753.76
A5: 4 | B5: 3695.77
A6: 5 | B6: 1571.88
A7: 6 | B7: 1999.93
A8: 7 | B8: 990.21
A9: 8 | B9: 1204.86
A10: 9 | B10: 474.38
A11: 10 | B11: 3296.58
A12: 11 | B12: 4264.44
A13: 12 | B13: 4243.93
... A41: 40 | B41: 1606.22
A42: Total | B42: =SUM(B2:B41) -> 107557.54

Sheet Store 11
A1: Day | B1: Takings
A2: 1 | B2: 627.46
A3: 2 | B3: 3737.78
A4: 3 | B4: 356.46
A5: 4 | B5: 4396.21
A6: 5 | B6: 3692.22
A7: 6 | B7: 560.26
A8: 7 | B8: 4158.5
A9: 8 | B9: 2958.49
A10: 9 | B10: 4234.69
A11: 10 | B11: 351.2
A12: 11 | B12: 4252.87
A13: 12 | B13: 2290.85
... A41: 40 | B41: 1593.05
A42: Total | B42: =SUM(B2:B41) -> 97461.37

Sheet Store 12
A1: Day | B1: Takings
A2: 1 | B2: 1169.64
A3: 2 | B3: 2011.34
A4: 3 | B4: 1891.99
A5: 4 | B5: 2188.34
A6: 5 | B6: 4425.91
A7: 6 | B7: 2883.64
A8: 7 | B8: 674.53
A9: 8 | B9: 4648.14
A10: 9 | B10: 1181.83
A11: 10 | B11: 4439.52
A12: 11 | B12: 2928.24
A13: 12 | B13: 4130.65
... A41: 40 | B41: 2263.13
A42: Total | B42: =SUM(B2:B41) -> 92811.99

Sheet Store 13
A1: Day | B1: Takings
A2: 1 | B2: 2209.03
A3: 2 | B3: 3071.64
A4: 3 | B4: 910.22
A5: 4 | B5: 202.91
A6: 5 | B6: 1594.11
A7: 6 | B7: 1416.29
A8: 7 | B8: 3548.99
A9: 8 | B9: 2274.34
A10: 9 | B10: 1537.79
A11: 10 | B11: 3400.95
A12: 11 | B12: 1583.81
A13: 12 | B13: 2146.38
... A41: 40 | B41: 556.43
A42: Total | B42: =SUM(B2:B41) -> 96876.49

Sheet Store 14
A1: Day | B1: Takings
A2: 1 | B2: 1775.44
A3: 2 | B3: 4516.01
A4: 3 | B4: 4185.54
A5: 4 | B5: 4501.83
A6: 5 | B6: 2546.62
A7: 6 | B7: 1544.45
A8: 7 | B8: 1553.4
A9: 8 | B9: 2390.64
A10: 9 | B10: 2196.85
A11: 10 | B11: 285.4
A12: 11 | B12: 1094.82
A13: 12 | B13: 3056.68
... A41: 40 | B41: 3909.98
A42: Total | B42: =SUM(B2:B41) -> 93769.79

Sheet Store 15
A1: Day | B1: Takings
A2: 1 | B2: 197.57
A3: 2 | B3: 3343.65
A4: 3 | B4: 4230.89
A5: 4 | B5: 2655.95
A6: 5 | B6: 2945.2
A7: 6 | B7: 611.54
A8: 7 | B8: 4135.27
A9: 8 | B9: 1346.06
A10: 9 | B10: 4121.39
A11: 10 | B11: 2058.08
A12: 11 | B12: 1586.97
A13: 12 | B13: 985.04
... A41: 40 | B41: 1883.7
A42: Total | B42: =SUM(B2:B41) -> 94101.87

Sheet Store 16
A1: Day | B1: Takings
A2: 1 | B2: 3169.4
A3: 2 | B3: 3473.98
A4: 3 | B4: 1487.57
A5: 4 | B5: 1122.35
A6: 5 | B6: 2498.35
A7: 6 | B7: 4531.59
A8: 7 | B8: 2752.5
A9: 8 | B9: 4933.46
A10: 9 | B10: 2071.39
A11: 10 | B11: 3028.85
A12: 11 | B12: 60.06
A13: 12 | B13: 527.1
... A41: 40 | B41: 58.11
A42: Total | B42: =SUM(B2:B41) -> 109958.62

Sheet Store 17
A1: Day | B1: Takings
A2: 1 | B2: 2355.84
A3: 2 | B3: 4302.33
A4: 3 | B4: 4.82
A5: 4 | B5: 2227.6
A6: 5 | B6: 2290.04
A7: 6 | B7: 738.54
A8: 7 | B8: 3645
A9: 8 | B9: 1188.82
A10: 9 | B10: 1097.37
A11: 10 | B11: 2954.34
A12: 11 | B12: 4117.48
A13: 12 | B13: 91.78
... A41: 40 | B41: 4016.95
A42: Total | B42: =SUM(B2:B41) -> 92048.42

Sheet Store 18
A1: Day | B1: Takings
A2: 1 | B2: 1692.03
A3: 2 | B3: 697.51
A4: 3 | B4: 2993.63
A5: 4 | B5: 720.55
A6: 5 | B6: 2682.27
A7: 6 | B7: 1850.03
A8: 7 | B8: 2899.39
A9: 8 | B9: 4407.49
A10: 9 | B10: 4966.28
A11: 10 | B11: 3013.6
A12: 11 | B12: 398.47
A13: 12 | B13: 827.75
... A41: 40 | B41: 1201.54
A42: Total | B42: =SUM(B2:B41) -> 87299.13

Sheet Store 19
A1: Day | B1: Takings
A2: 1 | B2: 4810.88
A3: 2 | B3: 2079.77
A4: 3 | B4: 829.84
A5: 4 | B5: 4156.91
A6: 5 | B6: 2769.53
A7: 6 | B7: 204.56
A8: 7 | B8: 592.38
A9: 8 | B9: 4283.7
A10: 9 | B10: 4326.73
A11: 10 | B11: 3747.48
A12: 11 | B12: 1951.88
A13: 12 | B13: 2733.82
... A41: 40 | B41: 2798.24
A42: Total | B42: =SUM(B2:B41) -> 99552.29

Sheet Store 20
A1: Day | B1: Takings
A2: 1 | B2: 4476.89
A3: 2 | B3: 4230.25
A4: 3 | B4: 1530.19
A5: 4 | B5: 4406.35
A6: 5 | B6: 4945.33
A7: 6 | B7: 2461.63
A8: 7 | B8: 1518.84
A9: 8 | B9: 3068.57
A10: 9 | B10: 3988.1
A11: 10 | B11: 3565.8
A12: 11 | B12: 1917.31
A13: 12 | B13: 4018.85
... A41: 40 | B41: 622.51
A42: Total | B42: =SUM(B2:B41) -> 117422.84

Sheet Store 21
A1: Day | B1: Takings
A2: 1 | B2: 2235.01
A3: 2 | B3: 3450.28
A4: 3 | B4: 2946.79
A5: 4 | B5: 571.81
A6: 5 | B6: 288.7
A7: 6 | B7: 2294.92
A8: 7 | B8: 258.05
A9: 8 | B9: 4545.43
A10: 9 | B10: 4585.75
A11: 10 | B11: 2492.79
A12: 11 | B12: 555.36
A13: 12 | B13: 1332.16
... A41: 40 | B41: 4499.29
A42: Total | B42: =SUM(B2:B41) -> 97967.14

Sheet Store 22
A1: Day | B1: Takings
A2: 1 | B2: 4334.34
A3: 2 | B3: 4352.62
A4: 3 | B4: 4262.36
A5: 4 | B5: 4643.93
A6: 5 | B6: 3558.14
A7: 6 | B7: 938.89
A8: 7 | B8: 4018.75
A9: 8 | B9: 1195.88
A10: 9 | B10: 3933.56
A11: 10 | B11: 1127.07
A12: 11 | B12: 3922.19
A13: 12 | B13: 905.32
... A41: 40 | B41: 3946.25
A42: Total | B42: =SUM(B2:B41) -> 113924.21

Sheet Store 23
A1: Day | B1: Takings
A2: 1 | B2: 3795.39
A3: 2 | B3: 2096.76
A4: 3 | B4: 4242.11
A5: 4 | B5: 3467.01
A6: 5 | B6: 4957.63
A7: 6 | B7: 22.9
A8: 7 | B8: 2012.46
A9: 8 | B9: 2503.54
A10: 9 | B10: 999.76
A11: 10 | B11: 1026.66
A12: 11 | B12: 1076.47
A13: 12 | B13: 435.36
... A41: 40 | B41: 4632.38
A42: Total | B42: =SUM(B2:B41) -> 100241.19

Sheet Store 24
A1: Day | B1: Takings
A2: 1 | B2: 4350
A3: 2 | B3: 1472.34
A4: 3 | B4: 1920.27
A5: 4 | B5: 86.14
A6: 5 | B6: 3852.32
A7: 6 | B7: 1898.66
A8: 7 | B8: 3445.82
A9: 8 | B9: 4898.53
A10: 9 | B10: 4764.15
A11: 10 | B11: 2555.77
A12: 11 | B12: 945.81
A13: 12 | B13: 3663.39
... A41: 40 | B41: 3188.4
A42: Total | B42: =SUM(B2:B41) -> 111991.86

Sheet Store 25
A1: Day | B1: Takings
A2: 1 | B2: 3764.28
A3: 2 | B3: 4130.61
A4: 3 | B4: 2389.01
A5: 4 | B5: 534.65
A6: 5 | B6: 1368.6
A7: 6 | B7: 314.16
A8: 7 | B8: 2221.43
A9: 8 | B9: 3868.71
A10: 9 | B10: 3559.5
A11: 10 | B11: 193.73
A12: 11 | B12: 1223.45
A13: 12 | B13: 1197.06
... A41: 40 | B41: 1064.24
A42: Total | B42: =SUM(B2:B41) -> 103391.83

Sheet Store 26
A1: Day | B1: Takings
A2: 1 | B2: 4459.54
A3: 2 | B3: 3966.47
A4: 3 | B4: 1102.31
A5: 4 | B5: 1810.28
A6: 5 | B6: 3920.33
A7: 6 | B7: 2816.02
A8: 7 | B8: 4734.7
A9: 8 | B9: 1572.88
A10: 9 | B10: 1034.43
A11: 10 | B11: 3782.49
A12: 11 | B12: 1487.1
A13: 12 | B13: 4822.63
... A41: 40 | B41: 1428.16
A42: Total | B42: =SUM(B2:B41) -> 109100

Sheet Store 27
A1: Day | B1: Takings
A2: 1 | B2: 1520.83
A3: 2 | B3: 3360.55
A4: 3 | B4: 4395.86
A5: 4 | B5: 1246.04
A6: 5 | B6: 1496.14
A7: 6 | B7: 178.3
A8: 7 | B8: 339.07
A9: 8 | B9: 736.66
A10: 9 | B10: 2100.12
A11: 10 | B11: 1110.26
A12: 11 | B12: 3925.77
A13: 12 | B13: 4985.78
... A41: 40 | B41: 1132.75
A42: Total | B42: =SUM(B2:B41) -> 98951.62

Sheet Store 28
A1: Day | B1: Takings
A2: 1 | B2: 1278.3
A3: 2 | B3: 2183.68
A4: 3 | B4: 4607.24
A5: 4 | B5: 2510.49
A6: 5 | B6: 1200.07
A7: 6 | B7: 532
A8: 7 | B8: 2193.12
A9: 8 | B9: 3642.83
A10: 9 | B10: 710.93
A11: 10 | B11: 1094.95
A12: 11 | B12: 4910.49
A13: 12 | B13: 4559.36
... A41: 40 | B41: 2758.22
A42: Total | B42: =SUM(B2:B41) -> 110283.72

Sheet Store 29
A1: Day | B1: Takings
A2: 1 | B2: 2107.1
A3: 2 | B3: 471.77
A4: 3 | B4: 2717.46
A5: 4 | B5: 2851.32
A6: 5 | B6: 622.92
A7: 6 | B7: 4460.13
A8: 7 | B8: 929.91
A9: 8 | B9: 4259.33
A10: 9 | B10: 2342.77
A11: 10 | B11: 4138.89
A12: 11 | B12: 1345.76
A13: 12 | B13: 2193.21
... A41: 40 | B41: 3625.12
A42: Total | B42: =SUM(B2:B41) -> 108556.11

Sheet Store 30
A1: Day | B1: Takings
A2: 1 | B2: 77.46
A3: 2 | B3: 2078.56
A4: 3 | B4: 2872.13
A5: 4 | B5: 3468.43
A6: 5 | B6: 416.1
A7: 6 | B7: 4998.02
A8: 7 | B8: 2734.47
A9: 8 | B9: 2333.37
A10: 9 | B10: 3690.49
A11: 10 | B11: 3949.44
A12: 11 | B12: 4768.6
A13: 12 | B13: 3452.54
... A41: 40 | B41: 4506.22
A42: Total | B42: =SUM(B2:B41) -> 111730.38

Sheet Store 31
A1: Day | B1: Takings
A2: 1 | B2: 1511.26
A3: 2 | B3: 1164.05
A4: 3 | B4: 1217.59
A5: 4 | B5: 3377.35
A6: 5 | B6: 302.05
A7: 6 | B7: 2863.58
A8: 7 | B8: 1035.46
A9: 8 | B9: 962.68
A10: 9 | B10: 2356.77
A11: 10 | B11: 4929.8
A12: 11 | B12: 355.06
A13: 12 | B13: 1636.25
... A41: 40 | B41: 865.22
A42: Total | B42: =SUM(B2:B41) -> 100643.89

Sheet Store 32
A1: Day | B1: Takings
A2: 1 | B2: 4325.1
A3: 2 | B3: 113.82
A4: 3 | B4: 2105.16
A5: 4 | B5: 2985.4
A6: 5 | B6: 3140.7
A7: 6 | B7: 1030.56
A8: 7 | B8: 1780.2
A9: 8 | B9: 2168.69
A10: 9 | B10: 549.99
A11: 10 | B11: 2336.79
A12: 11 | B12: 1081.53
A13: 12 | B13: 386.06
... A41: 40 | B41: 341.58
A42: Total | B42: =SUM(B2:B41) -> 84773.19

Sheet Store 33
A1: Day | B1: Takings
A2: 1 | B2: 3707.98
A3: 2 | B3: 1123.57
A4: 3 | B4: 1401.58
A5: 4 | B5: 613.99
A6: 5 | B6: 4077.21
A7: 6 | B7: 1990.23
A8: 7 | B8: 2685.17
A9: 8 | B9: 1063.95
A10: 9 | B10: 125.39
A11: 10 | B11: 2447.11
A12: 11 | B12: 1598.18
A13: 12 | B13: 1707.45
... A41: 40 | B41: 1047.96
A42: Total | B42: =SUM(B2:B41) -> 87208.95

Sheet Store 34
A1: Day | B1: Takings
A2: 1 | B2: 3055.18
A3: 2 | B3: 601.05
A4: 3 | B4: 3183.77
A5: 4 | B5: 4972.96
A6: 5 | B6: 866.33
A7: 6 | B7: 3226.33
A8: 7 | B8: 4288.5
A9: 8 | B9: 3991.05
A10: 9 | B10: 1937.01
A11: 10 | B11: 2565.21
A12: 11 | B12: 1280.83
A13: 12 | B13: 2654.79
... A41: 40 | B41: 1962.16
A42: Total | B42: =SUM(B2:B41) -> 91823.03

Sheet Store 35
A1: Day | B1: Takings
A2: 1 | B2: 2629.24
A3: 2 | B3: 2191.58
A4: 3 | B4: 4732.81
A5: 4 | B5: 3989.37
A6: 5 | B6: 2489.87
A7: 6 | B7: 815.58
A8: 7 | B8: 3943.77
A9: 8 | B9: 3223.82
A10: 9 | B10: 912.46
A11: 10 | B11: 2182.08
A12: 11 | B12: 1097.13
A13: 12 | B13: 2796.07
... A41: 40 | B41: 4065.48
A42: Total | B42: =SUM(B2:B41) -> 100079.79

Sheet Store 36
A1: Day | B1: Takings
A2: 1 | B2: 984.91
A3: 2 | B3: 2412.74
A4: 3 | B4: 1952.58
A5: 4 | B5: 2823.58
A6: 5 | B6: 1149.88
A7: 6 | B7: 2618.79
A8: 7 | B8: 4642.95
A9: 8 | B9: 1723.4
A10: 9 | B10: 1557.28
A11: 10 | B11: 3556.27
A12: 11 | B12: 116.61
A13: 12 | B13: 4649.93
... A41: 40 | B41: 3086.63
A42: Total | B42: =SUM(B2:B41) -> 88856.31

Sheet Store 37
A1: Day | B1: Takings
A2: 1 | B2: 933.27
A3: 2 | B3: 1472.1
A4: 3 | B4: 488.14
A5: 4 | B5: 3904.05
A6: 5 | B6: 1052.01
A7: 6 | B7: 2153.66
A8: 7 | B8: 3473.43
A9: 8 | B9: 3920.75
A10: 9 | B10: 4373
A11: 10 | B11: 2214.26
A12: 11 | B12: 501.17
A13: 12 | B13: 3378.95
... A41: 40 | B41: 2796.55
A42: Total | B42: =SUM(B2:B41) -> 99031.09

Sheet Store 38
A1: Day | B1: Takings
A2: 1 | B2: 4505.09
A3: 2 | B3: 314.48
A4: 3 | B4: 3385.37
A5: 4 | B5: 1536.29
A6: 5 | B6: 3612.57
A7: 6 | B7: 1121.49
A8: 7 | B8: 1580.64
A9: 8 | B9: 572.15
A10: 9 | B10: 2610.03
A11: 10 | B11: 1147.32
A12: 11 | B12: 3758.49
A13: 12 | B13: 104.42
... A41: 40 | B41: 2311.05
A42: Total | B42: =SUM(B2:B41) -> 94996.32

Sheet Store 39
A1: Day | B1: Takings
A2: 1 | B2: 1084.42
A3: 2 | B3: 3841.03
A4: 3 | B4: 1331.43
A5: 4 | B5: 2241.53
A6: 5 | B6: 621.13
A7: 6 | B7: 1854
A8: 7 | B8: 1554.53
A9: 8 | B9: 2733.87
A10: 9 | B10: 4067.61
A11: 10 | B11: 3411.75
A12: 11 | B12: 4386.15
A13: 12 | B13: 3421.01
... A41: 40 | B41: 84.21
A42: Total | B42: =SUM(B2:B41) -> 92050.63

Sheet Store 40
A1: Day | B1: Takings
A2: 1 | B2: 480.39
A3: 2 | B3: 1784.26
A4: 3 | B4: 2918.72
A5: 4 | B5: 1273.75
A6: 5 | B6: 1994.47
A7: 6 | B7: 698.62
A8: 7 | B8: 3489.73
A9: 8 | B9: 134.33
A10: 9 | B10: 193.66
A11: 10 | B11: 1029.88
A12: 11 | B12: 1592.88
A13: 12 | B13: 3488.1
... A41: 40 | B41: 3650.99
A42: Total | B42: =SUM(B2:B41) -> 88540.05

Sheet Store 41
A1: Day | B1: Takings
A2: 1 | B2: 4710.67
A3: 2 | B3: 3217.32
A4: 3 | B4: 2175.13
A5: 4 | B5: 329.21
A6: 5 | B6: 421.91
A7: 6 | B7: 4790.06
A8: 7 | B8: 13.18
A9: 8 | B9: 1628.76
A10: 9 | B10: 1198.05
A11: 10 | B11: 2469.1
A12: 11 | B12: 4864.57
A13: 12 | B13: 1949.9
... A41: 40 | B41: 3606.14
A42: Total | B42: =SUM(B2:B41) -> 105129.23

Sheet Store 42
A1: Day | B1: Takings
A2: 1 | B2: 1005.44
A3: 2 | B3: 2241
A4: 3 | B4: 2427.21
A5: 4 | B5: 3663.69
A6: 5 | B6: 486.45
A7: 6 | B7: 4938.39
A8: 7 | B8: 2179.08
A9: 8 | B9: 2149.88
A10: 9 | B10: 3430.22
A11: 10 | B11: 2249.48
A12: 11 | B12: 1070.02
A13: 12 | B13: 2547.94
... A41: 40 | B41: 1040
A42: Total | B42: =SUM(B2:B41) -> 106378.19

Sheet Store 43
A1: Day | B1: Takings
A2: 1 | B2: 1378.24
A3: 2 | B3: 1718.93
A4: 3 | B4: 3243.36
A5: 4 | B5: 277.38
A6: 5 | B6: 3841.98
A7: 6 | B7: 4394.91
A8: 7 | B8: 2861.81
A9: 8 | B9: 1148.78
A10: 9 | B10: 3431.1
A11: 10 | B11: 4837.3
A12: 11 | B12: 2053.28
A13: 12 | B13: 4213.46
... A41: 40 | B41: 802.59
A42: Total | B42: =SUM(B2:B41) -> 101177.62

Sheet Store 44
A1: Day | B1: Takings
A2: 1 | B2: 972.69
A3: 2 | B3: 2278.73
A4: 3 | B4: 2458.94
A5: 4 | B5: 2573.06
A6: 5 | B6: 3507.88
A7: 6 | B7: 2637.24
A8: 7 | B8: 2770.85
A9: 8 | B9: 498.44
A10: 9 | B10: 83.47
A11: 10 | B11: 2942.77
A12: 11 | B12: 836.32
A13: 12 | B13: 1963.6
... A41: 40 | B41: 341.3
A42: Total | B42: =SUM(B2:B41) -> 83238.88

Sheet Store 45
A1: Day | B1: Takings
A2: 1 | B2: 1599.26
A3: 2 | B3: 2553.67
A4: 3 | B4: 1919.07
A5: 4 | B5: 3761.73
A6: 5 | B6: 3594.15
A7: 6 | B7: 3041.03
A8: 7 | B8: 4583.92
A9: 8 | B9: 3857.77
A10: 9 | B10: 2827.96
A11: 10 | B11: 898.04
A12: 11 | B12: 3250.88
A13: 12 | B13: 726.99
... A41: 40 | B41: 685.96
A42: Total | B42: =SUM(B2:B41) -> 114068.9

Sheet Store 46
A1: Day | B1: Takings
A2: 1 | B2: 3510.49
A3: 2 | B3: 686.44
A4: 3 | B4: 1005.15
A5: 4 | B5: 227.24
A6: 5 | B6: 3996.31
A7: 6 | B7: 3481.68
A8: 7 | B8: 2360.6
A9: 8 | B9: 2835.46
A10: 9 | B10: 1394.39
A11: 10 | B11: 2333.23
A12: 11 | B12: 408.66
A13: 12 | B13: 3089.9
... A41: 40 | B41: 2534.43
A42: Total | B42: =SUM(B2:B41) -> 90892.53

Sheet Store 47
A1: Day | B1: Takings
A2: 1 | B2: 1093.59
A3: 2 | B3: 3465.28
A4: 3 | B4: 4156.46
A5: 4 | B5: 2009.28
A6: 5 | B6: 3468.3
A7: 6 | B7: 3207.49
A8: 7 | B8: 3492.04
A9: 8 | B9: 1377.89
A10: 9 | B10: 460.56
A11: 10 | B11: 3337.45
A12: 11 | B12: 4236.9
A13: 12 | B13: 3268.3
... A41: 40 | B41: 4203.57
A42: Total | B42: =SUM(B2:B41) -> 106420.7

Sheet Store 48
A1: Day | B1: Takings
A2: 1 | B2: 4271.25
A3: 2 | B3: 4927.37
A4: 3 | B4: 317.76
A5: 4 | B5: 898.6
A6: 5 | B6: 1910.58
A7: 6 | B7: 3079.48
A8: 7 | B8: 3372.88
A9: 8 | B9: 306.37
A10: 9 | B10: 3317.08
A11: 10 | B11: 1615.18
A12: 11 | B12: 4413.91
A13: 12 | B13: 2063.65
... A41: 40 | B41: 689.96
A42: Total | B42: =SUM(B2:B41) -> 101487.39

Sheet Store 49
A1: Day | B1: Takings
A2: 1 | B2: 484.31
A3: 2 | B3: 3869.36
A4: 3 | B4: 3538.24
A5: 4 | B5: 696.54
A6: 5 | B6: 310.38
A7: 6 | B7: 888.93
A8: 7 | B8: 2884.49
A9: 8 | B9: 3449.84
A10: 9 | B10: 3574.44
A11: 10 | B11: 3865.04
A12: 11 | B12: 4661.61
A13: 12 | B13: 264.01
... A41: 40 | B41: 2697.09
A42: Total | B42: =SUM(B2:B41) -> 106244.44

Sheet Store 50
A1: Day | B1: Takings
A2: 1 | B2: 59.83
A3: 2 | B3: 1791.04
A4: 3 | B4: 4711.75
A5: 4 | B5: 364.6
A6: 5 | B6: 3516.07
A7: 6 | B7: 3847.06
A8: 7 | B8: 4615.49
A9: 8 | B9: 2596.05
A10: 9 | B10: 4728.16
A11: 10 | B11: 4943.8
A12: 11 | B12: 2308.86
A13: 12 | B13: 1657.68
... A41: 40 | B41: 3109.06
A42: Total | B42: =SUM(B2:B41) -> 102142.34

Sheet Store 51
A1: Day | B1: Takings
A2: 1 | B2: 4659.85
A3: 2 | B3: 2280.69
A4: 3 | B4: 1639.05
A5: 4 | B5: 3696.09
A6: 5 | B6: 4756.4
A7: 6 | B7: 100
A8: 7 | B8: 4817.27
A9: 8 | B9: 3840.96
A10: 9 | B10: 3928.55
A11: 10 | B11: 107.55
A12: 11 | B12: 2326.53
A13: 12 | B13: 441.14
... A41: 40 | B41: 4468.4
A42: Total | B42: =SUM(B2:B41) -> 81198.85

Sheet Store 52
A1: Day | B1: Takings
A2: 1 | B2: 4341.02
A3: 2 | B3: 1470.43
A4: 3 | B4: 2376.53
A5: 4 | B5: 394.87
A6: 5 | B6: 1536.78
A7: 6 | B7: 3815.34
A8: 7 | B8: 89.95
A9: 8 | B9: 1106.53
A10: 9 | B10: 4941.65
A11: 10 | B11: 2199.1
A12: 11 | B12: 2913.1
A13: 12 | B13: 851.54
... A41: 40 | B41: 3027.98
A42: Total | B42: =SUM(B2:B41) -> 95929

Sheet Store 53
A1: Day | B1: Takings
A2: 1 | B2: 1432.74
A3: 2 | B3: 3736.45
A4: 3 | B4: 629.29
A5: 4 | B5: 3965.02
A6: 5 | B6: 4743.94
A7: 6 | B7: 3555.05
A8: 7 | B8: 4141.41
A9: 8 | B9: 878.42
A10: 9 | B10: 1627.97
A11: 10 | B11: 3291.2
A12: 11 | B12: 3871.4
A13: 12 | B13: 335.55
... A41: 40 | B41: 278.89
A42: Total | B42: =SUM(B2:B41) -> 111686.58

Sheet Store 54
A1: Day | B1: Takings
A2: 1 | B2: 4831.1
A3: 2 | B3: 1078.16
A4: 3 | B4: 4166.76
A5: 4 | B5: 571.73
A6: 5 | B6: 4499.45
A7: 6 | B7: 1612.08
A8: 7 | B8: 490.39
A9: 8 | B9: 2272.9
A10: 9 | B10: 2338.56
A11: 10 | B11: 502.9
A12: 11 | B12: 4623.86
A13: 12 | B13: 1062.21
... A41: 40 | B41: 2872.9
A42: Total | B42: =SUM(B2:B41) -> 103188.17

Sheet Store 55
A1: Day | B1: Takings
A2: 1 | B2: 1950.07
A3: 2 | B3: 817.89
A4: 3 | B4: 909.63
A5: 4 | B5: 787.22
A6: 5 | B6: 3348.45
A7: 6 | B7: 3628.45
A8: 7 | B8: 2966
A9: 8 | B9: 2996.21
A10: 9 | B10: 3819.34
A11: 10 | B11: 486.92
A12: 11 | B12: 4825.2
A13: 12 | B13: 1421.56
... A41: 40 | B41: 729.19
A42: Total | B42: =SUM(B2:B41) -> 87593.3

Sheet Store 56
A1: Day | B1: Takings
A2: 1 | B2: 3966.53
A3: 2 | B3: 221.69
A4: 3 | B4: 2391.2
A5: 4 | B5: 4077.53
A6: 5 | B6: 3728.01
A7: 6 | B7: 37.36
A8: 7 | B8: 4954.7
A9: 8 | B9: 2135
A10: 9 | B10: 4221.09
A11: 10 | B11: 4949.35
A12: 11 | B12: 985.47
A13: 12 | B13: 2578.68
... A41: 40 | B41: 904.65
A42: Total | B42: =SUM(B2:B41) -> 100971.3

Sheet Store 57
A1: Day | B1: Takings
A2: 1 | B2: 3726.47
A3: 2 | B3: 4964.4
A4: 3 | B4: 4368.68
A5: 4 | B5: 927.35
A6: 5 | B6: 3218.82
A7: 6 | B7: 1541.65
A8: 7 | B8: 3699.97
A9: 8 | B9: 1036.14
A10: 9 | B10: 28.25
A11: 10 | B11: 1561.63
A12: 11 | B12: 4130.8
A13: 12 | B13: 1204.56
... A41: 40 | B41: 3799.99
A42: Total | B42: =SUM(B2:B41) -> 102392.77

Sheet Store 58
A1: Day | B1: Takings
A2: 1 | B2: 669.95
A3: 2 | B3: 4016.79
A4: 3 | B4: 3340.51
A5: 4 | B5: 1916.63
A6: 5 | B6: 3987.43
A7: 6 | B7: 4044.14
A8: 7 | B8: 1272.58
A9: 8 | B9: 4069.68
A10: 9 | B10: 1785.32
A11: 10 | B11: 3722.34
A12: 11 | B12: 2260.77
A13: 12 | B13: 2404.57
... A41: 40 | B41: 4147.56
A42: Total | B42: =SUM(B2:B41) -> 94360.95

Sheet Store 59
A1: Day | B1: Takings
A2: 1 | B2: 624.7
A3: 2 | B3: 2025.2
A4: 3 | B4: 1793.79
A5: 4 | B5: 3062.09
A6: 5 | B6: 4720.56
A7: 6 | B7: 1897.35
A8: 7 | B8: 634.56
A9: 8 | B9: 1295.74
A10: 9 | B10: 1432.55
A11: 10 | B11: 4482.51
A12: 11 | B12: 4151.42
A13: 12 | B13: 2309.6
... A41: 40 | B41: 1936.93
A42: Total | B42: =SUM(B2:B41) -> 88012.43

Sheet Store 60
A1: Day | B1: Takings
A2: 1 | B2: 4067.43
A3: 2 | B3: 1269.39
A4: 3 | B4: 2764.72
A5: 4 | B5: 845.69
A6: 5 | B6: 1839.88
A7: 6 | B7: 1483.01
A8: 7 | B8: 1349.02
A9: 8 | B9: 3853.15
A10: 9 | B10: 1987.13
A11: 10 | B11: 2884.65
A12: 11 | B12: 3152.76
A13: 12 | B13: 336.33
... A41: 40 | B41: 782.87
A42: Total | B42: =SUM(B2:B41) -> 103201.93
